<?xml version="1.0"?>
<robot xmlns:xacro="http://www.ros.org/wiki/xacro">

    <xacro:include filename = "inertial_macros.xacro" />

    <!-- Colors -->
    <material name="white">
        <color rgba= "1 1 1 1"/>    
    </material>
    
    <material name="black">
        <color rgba= "0 0 0 1"/>    
    </material>
    
    <material name= "orange">
        <color rgba= "1 0.25 0 1"/>    
    </material>

    <material name="cyan">
        <color rgba= "0 1 1 1"/>    
    </material>

    <material name="indigo">
        <color rgba= "0.294 0 0.51 1"/>    
    </material>


    <!-- convention (except base_link): joint followed by link -->
    <!-- base_link -->
    <link name="base_link">
    </link>

    <!-- base_footprint -->
    <joint name="base_footprint_joint" type="fixed">
        <parent link= "base_link"/>
        <child link= "base_footprint"/>
        <origin xyz= "0 0 0" rpy= "0 0 0"/>    
    </joint>

    <link name="base_footprint">
    </link>

    <!-- chasis -->
    <joint name="chasis_joint" type="fixed">
        <parent link= "base_link"/>
        <child link= "chasis"/>
        <origin xyz= "-0.1 0 0"/>    
    </joint>

    <link name="chasis">
        <visual>
            <origin xyz= "0.15 0 0.075" rpy= "0 0 0"/>
            <geometry>
                <box size = "0.3 0.3 0.15"/>
            </geometry>
            <material name= "black"/>
        </visual>
        <collision>
            <origin xyz= "0.15 0 0.075" rpy= "0 0 0"/>
            <geometry>
                <box size = "0.3 0.3 0.15"/>
            </geometry>
        </collision>
        <xacro:inertial_box mass= "0.5" x="0.3" y="0.3" z="0.15">
            <origin xyz= "0.15 0 0.075" rpy= "0 0 0"/>
        </xacro:inertial_box>
    </link> 

    <gazebo reference="chasis">
        <material>Gazebo/Black</material>
    </gazebo>

    <!-- left_wheel -->
    <joint name="left_wheel_joint" type="continuous">
        <parent link= "base_link"/>
        <child link= "left_wheel"/>
        <origin xyz= "0 0.17 0" rpy = "${pi/2} 0 0"/>
        <axis xyz= "0 0 -1"/>    
    </joint>

    <link name="left_wheel"> 
        <visual>
            <geometry>
                <cylinder radius = "0.05" length= "0.04"/>
            </geometry>
            <material name= "orange"/>
        </visual>
        <collision>
            <geometry>
                <sphere radius = "0.05" />
            </geometry>
        </collision>
        <xacro:inertial_cylinder mass = "0.1" radius= "0.05" length= "0.04">
            <origin xyz= "0 0 0" rpy= "0 0 0"/>
        </xacro:inertial_cylinder>
    </link> 

    <gazebo reference="left_wheel">
        <material>Gazebo/Orange</material>
    </gazebo>

    <!-- right_wheel -->
    <joint name="right_wheel_joint" type="continuous">
        <parent link= "base_link"/>
        <child link= "right_wheel"/>
        <origin xyz= "0 -0.17 0" rpy = "${pi/2} 0 0"/>
        <axis xyz= "0 0 -1"/>    
    </joint>

    <link name="right_wheel"> 
        <visual>
            <geometry>
                <cylinder radius = "0.05" length= "0.04"/>
            </geometry>
            <material name= "orange"/>
        </visual>
        <collision>
            <geometry>
                <sphere radius = "0.05" />
            </geometry>
        </collision>
        <xacro:inertial_cylinder mass= "0.1" radius= "0.05" length= "0.04">
            <origin xyz= "0 0 0" rpy= "0 0 0"/>
        </xacro:inertial_cylinder>
    </link> 

    <gazebo reference="right_wheel">
        <material>Gazebo/Orange</material>
    </gazebo>

    <!-- caster_wheel -->
    <joint name="caster_wheel_joint" type="fixed">
        <parent link= "chasis"/>
        <child link= "caster_wheel"/>
        <origin xyz= "0.24 0 0"/>   
    </joint>

    <link name="caster_wheel"> 
        <visual>
            <geometry>
                <sphere radius = "0.05"/>
            </geometry>
            <material name= "orange"/>
        </visual>
        <collision>
            <geometry>
                <sphere radius = "0.05"/>
            </geometry>
        </collision>
        <xacro:inertial_sphere mass= "0.1" radius= "0.05">
            <origin xyz= "0 0 0" rpy= "0 0 0"/>
        </xacro:inertial_sphere>
    </link> 

    <gazebo reference="caster_wheel">
        <material>Gazebo/Orange</material>
        <mu1 value= "0.0001"/>
        <mu2 value= "0.0001"/>
    </gazebo>


</robot>